Workbook
Name Amount: Inputs!$D$3
Name Assets: PFS!$C$31
Name Cash: #REF!
Name Cash_Reserve: Inputs!$D$10
Name Contract_Remain: Contract!$C$23
Name Contract_Y1: Contract!$C$18
Name Contract_Y2: Contract!$C$20
Name Contract_Y3: Contract!$C$21
Name Contract_Y4: Contract!$C$22
Name Credit_Score: Inputs!$D$18
Name Debt_mnth: Inputs!$D$16
Name DSCR: 'Cash Flow'!$G$29
Name income_mnth: Inputs!$D$15
Name insurance: Inputs!$D$8
Name interest_Reserve: Inputs!$D$9
Name intrest_Reserve: Inputs!$D$9
Name LenderReturn: Schedule!$F$46
Name Liabilities: PFS!$F$31
Name Net_Worth: PFS!#REF!
Name Orig_Fee: Inputs!$D$6
Name PMT_Mnth: Inputs!$D$12
Name Proceeds: Schedule!$K$20
Name rate: Inputs!$D$4
Name Salary_Contract: Contract!$C$24
Name Salary_Remain: Contract!$C$23
Name Term: Inputs!$D$5
Name Total_Contract: Contract!$C$24
Name Upfront: Inputs!$D$11
Name UW_Fee: Inputs!$D$7

Sheet NBA CONTRACT LOAN
B2: CONTRACT LOAN - CREDIT ANALYSIS
B3: Player A | $10,250,000 Guaranteed Contract Facility | February 2025
B4: Tab | C4: Description | D4: Reference
B5: Summary | C5: Credit memorandum summarizing the proposed facility | D5: Tab 1
B6: Guidelines | C6: Underwriting standards compliance table, key ratios, risk flags, and 5 C's scoring narrative. | D6: Tab 2
B7: Cash Flow | C7: Four-year personal cash flow detailing net cash available for debt service | D7: Tab 3
B8: Schedule | C8: Full 36-month amortization schedule with deferral period | D8: Tab 4
B9: Sensitivity | C9: Dual sensitivity analysis stress-testing total interest income and minimum annual DSCR across 30 rate and term scenarios | D9: Tab 5
B10: Inputs | C10: Centralized deal inputs; loan parameters, fee structure, mortgage debts | D10: Tab 6
B11: PFS | C11: Personal financial statement | D11: Tab 7
B12: Contract | C12: Uniform Player Contract compensation with analysis. | D12: Tab 8
B14: *Sample deal for demonstration purposes only. All data is fictional. Prepared independently by Kristen Gallagher.

Sheet Summary
B1: CREDIT MEMORANDUM
B23: Capital | C23: 2 | E23: Proposed Facility Terms & Conditions
B24: Collateral | C24: 3 | E24: Borrower | F24: Player A
B25: Character | C25: 2 | E25: Loan Type | F25: NBA Guaranteed Contract Loan
B26: Capacity | C26: 2 | E26: Purpose of Proposed Facility | F26: Contract advance; Invest in franchises
B27: Conditions | C27: 2 | E27: Proposed Commitment | F27: =Amount -> 10250000
E28: Term | F28: 36 Months
B29: Prepared by: | C29: Kristen Gallagher | E29: Interest Rate | F29: 0.13
B30: Date: | C30: 45693 | E30: Underwriting Fee | F30: 0.03
B31: *Sample deal for demonstration purposes only. All data is fictional. | E31: Origination Fee | F31: 0.01
E32: Interest Reserve | F32: =interest_Reserve -> 727689
B33: Recommendation | C33: Approved | E33: Collateral | F33: Remaining NBA Contract ($86,932,818)
E34: Prepayment Penalty | F34: None
E35: Proposed Maturity | F35: November 1, 2027 Coterminous with the NBA Contract for the 2024-2027 seasons
E36: Guarantor(s) | F36: Player A
E37: Amortization Schedule (Reference Schedule Tab) | F37: Year 2024: No payments, interest reserve cover through November 1, 2025. December 1, 2025 – November 1, 2026: 12 monthly principal & interest ~ $5,847,644 total. December 1, 2026 – November 1, 2027: 12 monthly principal & interest ~$5,847,644 total
E38: Primary Repayment Source | F38: Cash Flow from NBA Contract
E39: Protections (A) | F39: Death, Dishonor, & Disgrace insurance provided through Insurer A
E40: Protections (B) | F40: Enforcement of full Guarantee provided by Borrower
E41: Balloon at Maturity | F41: N/A

Sheet Guidelines
B2: Ratio | E2: Underwriting Standards: Type | F2: Guidelines | G2: Pro Forma - Player | H2: In Compliance Y/N
B3: DSCR | C3: =DSCR -> 4.3325404 | E3: Maximum LTC | F3: 0.25 | G3: =Amount/Salary_Remain -> 0.1179085 | H3: Yes
B4: LTCg (LTV) | C4: =Amount/Salary_Remain -> 0.1179085 | E4: Minimum Average DSCR | F4: 2.5 | G4: =DSCR -> 4.3325404 | H4: Yes
B5: DTA | C5: =Liabilities/Assets -> 0.16781624 | E5: Minimum Cash Equity | F5: 0.1 | G5: 0.1 | H5: Yes
B6: Interest Coverage | C6: =('Cash Flow'!D15)/(Inputs!D3*Inputs!D4) -> 12.25776 | E6: Maximum Term | F6: 36 Months | G6: 36 Months | H6: Yes
B7: Credit Score | C7: =Credit_Score -> 680 | E7: Maximum Amortization | F7: 36 Months | G7: 24 Months | H7: Yes
B8: Disposable Income (Net) | C8: ='Cash Flow'!G28/Salary_Contract -> 0.40497776 | E8: Direct Deposit | F8: Required | G8: Provided | H8: Yes
B9: Collateral Coverage | C9: =Salary_Remain/Amount -> 8.481153 | E9: Personal Guarantee | F9: Full Recourse | G9: Full Recourse | H9: Yes
B10: Liquidity (Months) | C10: =(PFS!C6+PFS!C7)/Debt_mnth -> 57.494373 | E10: Maximum DTA | F10: 0.5 | G10: =Liabilities/Assets -> 0.16781624 | H10: Yes
B11: DTI | C11: =Debt_mnth/income_mnth -> 0.023268263 | E11: Credit Score | F11: 675 | G11: 680 | H11: Yes
B12: DTI Pro Forma | C12: =(Debt_mnth+PMT_Mnth)/income_mnth -> 0.21176375
B14: *Disposable Income reflects average net cash flow across the full loan term as a percentage of total contract value. DSCR reflects average annual debt service coverage across active repayment periods.
B16: RISK FLAGS & MITIGANTS
B17: Risk Factor | C17: Description | D17: Severity | E17: Mitigant | F17: Residual Risk
B18: Year-4 DSCR Deterioration | C18: Minimum annual DSCR declines to 2.16x in the 2026-27 season as guaranteed salary steps down to $26.9M, falling below the 2.50x guideline floor on an annual basis. | D18: MEDIUM | E18: Interest reserve, 10% cash depository, and collateral coverage of 8.48x provide sufficient liquidity buffer. Lender-controlled direct deposit ensures payment continuity regardless of borrower cash management. | F18: LOW
B19: Below-Average Credit Score | C19: Borrower credit score of 680 is below average for a facility of this size. One prior missed payment noted, since resolved. Four accounts currently in good standing. | D19: LOW | E19: Full personal guarantee and guaranteed contract income significantly reduce reliance on borrower creditworthiness. Active monitoring required throughout loan term. | F19: LOW
B20: Speculative Use of Proceeds | C20: Loan proceeds designated for franchise investment — an illiquid, speculative asset with no guaranteed return or direct income offset against loan obligations. | D20: MEDIUM | E20: Repayment sourced entirely from guaranteed NBA contract cash flow, Franchise investment does not affect repayment capacity. DDD insurance provides catastrophic loss protection. | F20: LOW

Sheet Cash Flow
B2: Personal Cash Flow Analysis
D3: Pro Forma
C4: 2023-24 | D4: 2024-25 | E4: 2025-26 | F4: 2026-27 | G4: Totals
B5: Salary (Professional Contract) | C5: =Contract_Y1 -> 33068182 | D5: =Contract_Y2 -> 31022727 | E5: =Contract_Y3 -> 28977273 | F5: =Contract_Y4 -> 26931818 | G5: =SUM(C5:F5) -> 120000000
B6: GROSS CASH FLOW | C6: =C5 -> 33068182 | D6: =D5 -> 31022727 | E6: =E5 -> 28977273 | F6: =F5 -> 26931818 | G6: =SUM(C6:F6) -> 120000000
B7: Less:
B8: Escrow (10%) | C8: =C5*0.1 -> 3306818.2 | D8: =D5*0.1 -> 3102272.7 | E8: =E5*0.1 -> 2897727.3 | F8: =F5*0.1 -> 2693181.8 | G8: =SUM(C8:F8) -> 12000000
B9: Federal/Other Taxes (Est @ 35%) | C9: =(C5-C8)*0.35 -> 10416477 | D9: =(D5-D8)*0.35 -> 9772159 | E9: =(E5-E8)*0.35 -> 9127841 | F9: =(F5-F8)*0.35 -> 8483522.7 | G9: =SUM(C9:F9) -> 37800000
B11: Net Cash Flow | C11: =C5-C8-C9 -> 19344886 | D11: =D5-D8-D9 -> 18148295 | E11: =E5-E8-E9 -> 16951705 | F11: =F5-F8-F9 -> 15755114 | G11: =SUM(C11:F11) -> 70200000
B12: Less:
B13: Living Expenses (Est @ 10% of income) | C13: =C11*0.1 -> 1934488.6 | D13: =D11*0.1 -> 1814829.5 | E13: =E11*0.1 -> 1695170.5 | F13: =F11*0.1 -> 1575511.4 | G13: =SUM(C13:F13) -> 7020000
B15: AVAILABLE FOR DEBT | C15: =C11-C13 -> 17410398 | D15: =D11-D13 -> 16333466 | E15: =E11-E13 -> 15256534 | F15: =F11-F13 -> 14179602 | G15: =SUM(C15:F15) -> 63180000
B17: Less:
B18: Estimated Guaranteed Contract Loan (@ 13%) | C18: 0 | D18: 0 | E18: =PMT(rate/12,(Term-12),-Amount)*12 -> 5847644.2 | F18: =PMT(rate/12,(Term-12),-Amount)*12 -> 5847644.2 | G18: =SUM(C18:F18) -> 11695288
B19: Mortgage (709 Palmview Drive, FL) | C19: =Inputs!$D$24*12 -> 230280 | D19: =Inputs!$D$24*12 -> 230280 | E19: =Inputs!$D$24*12 -> 230280 | F19: =Inputs!$D$24*12 -> 230280 | G19: =SUM(C19:F19) -> 921120
B20: Mortgage (123 Brookstone Manor, NY) | C20: =Inputs!$D$23*12 -> 114300 | D20: =Inputs!$D$23*12 -> 114300 | E20: =Inputs!$D$23*12 -> 114300 | F20: =Inputs!$D$23*12 -> 114300 | G20: =SUM(C20:F20) -> 457200
B21: Mortgage (7 & 15 South Street, CA) | C21: =Inputs!$D$27*12 -> 80664 | D21: =Inputs!$D$27*12 -> 80664 | E21: =Inputs!$D$27*12 -> 80664 | F21: =Inputs!$D$27*12 -> 80664 | G21: =SUM(C21:F21) -> 322656
B22: Mortgage (33276 Queens Colony, MD) | C22: =Inputs!$D$25*12 -> 38400 | D22: =Inputs!$D$25*12 -> 38400 | E22: =Inputs!$D$25*12 -> 38400 | F22: =Inputs!$D$25*12 -> 38400 | G22: =SUM(C22:F22) -> 153600
B23: Automobile | C23: =PMT(0.035/12, 39, -55836)*12 -> 18200.974 | D23: =PMT(0.035/12, 39, -55836)*12 -> 18200.974 | E23: =PMT(0.035/12, 39, -55836)*12 -> 18200.974 | F23: =PMT(0.035/12, 39, -55836)*12 -> 18200.974 | G23: =SUM(C23:F23) -> 72803.896
B24: Pierce Advisors (@10%) | C24: =PFS!$F$9*0.1 -> 190000 | D24: =PFS!$F$9*0.1 -> 190000 | E24: =PFS!$F$9*0.1 -> 190000 | F24: =PFS!$F$9*0.1 -> 190000 | G24: =SUM(C24:F24) -> 760000
B25: Credit Cards | C25: 50000 | D25: 50000 | E25: 50000 | F25: 50000 | G25: =SUM(C25:F25) -> 200000
B26: TOTAL DEBT | C26: =SUM(C18:C25) -> 721844.97 | D26: =SUM(D18:D25) -> 721844.97 | E26: =SUM(E18:E25) -> 6569489.2 | F26: =SUM(F18:F25) -> 6569489.2 | G26: =SUM(C26:F26) -> 14582668
B28: NET CASH FLOW | C28: =C15-C26 -> 16688553 | D28: =D15-D26 -> 15611621 | E28: =E15-E26 -> 8687045.1 | F28: =F15-F26 -> 7610113 | G28: =SUM(C28:F28) -> 48597332
B29: DEBT SERVICE RATIO | C29: =C15/C26 -> 24.119303 | D29: =D15/D26 -> 22.627387 | E29: =E15/E26 -> 2.3223319 | F29: =F15/F26 -> 2.1584026 | G29: =G15/G26 -> 4.3325404

Sheet Schedule
B1: $10.25M Loan Amortization Schedule
J2: Gross Loan Amount | K2: 10250000
B3: PMT # | C3: Date | D3: Beg Balance | E3: Interest | F3: Principal | G3: Total PMT | H3: End Balance | J3: Interest | K3: =rate -> 0.13
B4: 1 | C4: 45627 | D4: =Amount -> 10250000 | E4: 0 | F4: =Schedule!$G4-Schedule!$E4 -> 0 | G4: 0 | H4: =D4-F4 -> 10250000 | J4: Term (Months) | K4: =Term -> 36
B5: =B4+1 -> 2 | C5: =EDATE(C4, 1) -> 45658 | D5: =H4 -> 10250000 | E5: 0 | F5: =Schedule!$G5-Schedule!$E5 -> 0 | G5: 0 | H5: =D5-F5 -> 10250000 | J5: Origination Fee (1%) | K5: =Orig_Fee -> 102500
B6: =B5+1 -> 3 | C6: =EDATE(C5, 1) -> 45689 | D6: =H5 -> 10250000 | E6: 0 | F6: =Schedule!$G6-Schedule!$E6 -> 0 | G6: 0 | H6: =D6-F6 -> 10250000 | J6: Underwriting Fee (3%) | K6: =UW_Fee -> 307500
B7: =B6+1 -> 4 | C7: =EDATE(C6, 1) -> 45717 | D7: =H6 -> 10250000 | E7: 0 | F7: =Schedule!$G7-Schedule!$E7 -> 0 | G7: 0 | H7: =D7-F7 -> 10250000 | J7: Death & Disgrace Insurance (est) | K7: =insurance -> 190050
B8: =B7+1 -> 5 | C8: =EDATE(C7, 1) -> 45748 | D8: =H7 -> 10250000 | E8: 0 | F8: =Schedule!$G8-Schedule!$E8 -> 0 | G8: 0 | H8: =D8-F8 -> 10250000 | J8: Interest Reserve (est) | K8: =interest_Reserve -> 727689
B9: =B8+1 -> 6 | C9: =EDATE(C8, 1) -> 45778 | D9: =H8 -> 10250000 | E9: 0 | F9: =Schedule!$G9-Schedule!$E9 -> 0 | G9: 0 | H9: =D9-F9 -> 10250000 | J9: Cash Reserve (Depository Acct) 10% of outstanding balance | K9: =Cash_Reserve -> 1025000
B10: =B9+1 -> 7 | C10: =EDATE(C9, 1) -> 45809 | D10: =H9 -> 10250000 | E10: 0 | F10: =Schedule!$G10-Schedule!$E10 -> 0 | G10: 0 | H10: =D10-F10 -> 10250000 | J10: Total Upfront | K10: =SUM(K5:K9) -> 2352739
B11: =B10+1 -> 8 | C11: =EDATE(C10, 1) -> 45839 | D11: =H10 -> 10250000 | E11: 0 | F11: =Schedule!$G11-Schedule!$E11 -> 0 | G11: 0 | H11: =D11-F11 -> 10250000 | J11: Monthly PMT | K11: =PMT_Mnth -> 487303.68
B12: =B11+1 -> 9 | C12: =EDATE(C11, 1) -> 45870 | D12: =H11 -> 10250000 | E12: 0 | F12: =Schedule!$G12-Schedule!$E12 -> 0 | G12: 0 | H12: =D12-F12 -> 10250000 | J12: Annual Debt service | K12: =PMT_Mnth*12 -> 5847644.2
B13: =B12+1 -> 10 | C13: =EDATE(C12, 1) -> 45901 | D13: =H12 -> 10250000 | E13: 0 | F13: =Schedule!$G13-Schedule!$E13 -> 0 | G13: 0 | H13: =D13-F13 -> 10250000 | J13: DSCR | K13: =DSCR -> 4.3325404
B14: =B13+1 -> 11 | C14: =EDATE(C13, 1) -> 45931 | D14: =H13 -> 10250000 | E14: 0 | F14: =Schedule!$G14-Schedule!$E14 -> 0 | G14: 0 | H14: =D14-F14 -> 10250000
B15: =B14+1 -> 12 | C15: =EDATE(C14, 1) -> 45962 | D15: =H14 -> 10250000 | E15: 0 | F15: =Schedule!$G15-Schedule!$E15 -> 0 | G15: 0 | H15: =D15-F15 -> 10250000 | J15: Load Proceeds:
B16: =B15+1 -> 13 | C16: =EDATE(C15, 1) -> 45992 | D16: =H15 -> 10250000 | E16: =D16*(rate/12) -> 111041.67 | F16: =G16-E16 -> 376262.01 | G16: =PMT(rate/12, Term-12, -Amount) -> 487303.68 | H16: =D16-F16 -> 9873738 | J16: Gross Loan Amount | K16: =Amount -> 10250000
B17: =B16+1 -> 14 | C17: =EDATE(C16, 1) -> 46023 | D17: =H16 -> 9873738 | E17: =D17*(rate/12) -> 106965.49 | F17: =G17-E17 -> 380338.19 | G17: =PMT(rate/12, Term-12, -Amount) -> 487303.68 | H17: =D17-F17 -> 9493399.8 | J17: Lender Origination Fee (Est) | K17: =-Orig_Fee -> -102500
B18: =B17+1 -> 15 | C18: =EDATE(C17, 1) -> 46054 | D18: =H17 -> 9493399.8 | E18: =D18*(rate/12) -> 102845.16 | F18: =G18-E18 -> 384458.52 | G18: =PMT(rate/12, Term-12, -Amount) -> 487303.68 | H18: =D18-F18 -> 9108941.3 | J18: Underwriting Fee (Est) | K18: =-UW_Fee -> -307500
B19: =B18+1 -> 16 | C19: =EDATE(C18, 1) -> 46082 | D19: =H18 -> 9108941.3 | E19: =D19*(rate/12) -> 98680.197 | F19: =G19-E19 -> 388623.48 | G19: =PMT(rate/12, Term-12, -Amount) -> 487303.68 | H19: =D19-F19 -> 8720317.8 | J19: Legal/Closing Costs (Est) | K19: -22000
B20: =B19+1 -> 17 | C20: =EDATE(C19, 1) -> 46113 | D20: =H19 -> 8720317.8 | E20: =D20*(rate/12) -> 94470.109 | F20: =G20-E20 -> 392833.57 | G20: =PMT(rate/12, Term-12, -Amount) -> 487303.68 | H20: =D20-F20 -> 8327484.2 | J20: To be disbursed to Borrower (Est) | K20: 5003600
B21: =B20+1 -> 18 | C21: =EDATE(C20, 1) -> 46143 | D21: =H20 -> 8327484.2 | E21: =D21*(rate/12) -> 90214.412 | F21: =G21-E21 -> 397089.27 | G21: =PMT(rate/12, Term-12, -Amount) -> 487303.68 | H21: =D21-F21 -> 7930395 | J21: Death & Disgrace Insurance (Est) | K21: =-insurance -> -190050
B22: =B21+1 -> 19 | C22: =EDATE(C21, 1) -> 46174 | D22: =H21 -> 7930395 | E22: =D22*(rate/12) -> 85912.612 | F22: =G22-E22 -> 401391.07 | G22: =PMT(rate/12, Term-12, -Amount) -> 487303.68 | H22: =D22-F22 -> 7529003.9 | J22: Net to be Disbursed to Borrower (Est) | K22: =Proceeds+K21 -> 4813550
B23: =B22+1 -> 20 | C23: =EDATE(C22, 1) -> 46204 | D23: =H22 -> 7529003.9 | E23: =D23*(rate/12) -> 81564.209 | F23: =G23-E23 -> 405739.47 | G23: =PMT(rate/12, Term-12, -Amount) -> 487303.68 | H23: =D23-F23 -> 7123264.4
B24: =B23+1 -> 21 | C24: =EDATE(C23, 1) -> 46235 | D24: =H23 -> 7123264.4 | E24: =D24*(rate/12) -> 77168.698 | F24: =G24-E24 -> 410134.98 | G24: =PMT(rate/12, Term-12, -Amount) -> 487303.68 | H24: =D24-F24 -> 6713129.4
B25: =B24+1 -> 22 | C25: =EDATE(C24, 1) -> 46266 | D25: =H24 -> 6713129.4 | E25: =D25*(rate/12) -> 72725.569 | F25: =G25-E25 -> 414578.11 | G25: =PMT(rate/12, Term-12, -Amount) -> 487303.68 | H25: =D25-F25 -> 6298551.3
B26: =B25+1 -> 23 | C26: =EDATE(C25, 1) -> 46296 | D26: =H25 -> 6298551.3 | E26: =D26*(rate/12) -> 68234.306 | F26: =G26-E26 -> 419069.38 | G26: =PMT(rate/12, Term-12, -Amount) -> 487303.68 | H26: =D26-F26 -> 5879481.9
B27: =B26+1 -> 24 | C27: =EDATE(C26, 1) -> 46327 | D27: =H26 -> 5879481.9 | E27: =D27*(rate/12) -> 63694.388 | F27: =G27-E27 -> 423609.29 | G27: =PMT(rate/12, Term-12, -Amount) -> 487303.68 | H27: =D27-F27 -> 5455872.6
B28: =B27+1 -> 25 | C28: =EDATE(C27, 1) -> 46357 | D28: =H27 -> 5455872.6 | E28: =D28*(rate/12) -> 59105.287 | F28: =G28-E28 -> 428198.39 | G28: =PMT(rate/12, Term-12, -Amount) -> 487303.68 | H28: =D28-F28 -> 5027674.3
B29: =B28+1 -> 26 | C29: =EDATE(C28, 1) -> 46388 | D29: =H28 -> 5027674.3 | E29: =D29*(rate/12) -> 54466.471 | F29: =G29-E29 -> 432837.21 | G29: =PMT(rate/12, Term-12, -Amount) -> 487303.68 | H29: =D29-F29 -> 4594837
B30: =B29+1 -> 27 | C30: =EDATE(C29, 1) -> 46419 | D30: =H29 -> 4594837 | E30: =D30*(rate/12) -> 49777.401 | F30: =G30-E30 -> 437526.28 | G30: =PMT(rate/12, Term-12, -Amount) -> 487303.68 | H30: =D30-F30 -> 4157310.8
B31: =B30+1 -> 28 | C31: =EDATE(C30, 1) -> 46447 | D31: =H30 -> 4157310.8 | E31: =D31*(rate/12) -> 45037.533 | F31: =G31-E31 -> 442266.15 | G31: =PMT(rate/12, Term-12, -Amount) -> 487303.68 | H31: =D31-F31 -> 3715044.6
B32: =B31+1 -> 29 | C32: =EDATE(C31, 1) -> 46478 | D32: =H31 -> 3715044.6 | E32: =D32*(rate/12) -> 40246.317 | F32: =G32-E32 -> 447057.36 | G32: =PMT(rate/12, Term-12, -Amount) -> 487303.68 | H32: =D32-F32 -> 3267987.2
B33: =B32+1 -> 30 | C33: =EDATE(C32, 1) -> 46508 | D33: =H32 -> 3267987.2 | E33: =D33*(rate/12) -> 35403.195 | F33: =G33-E33 -> 451900.49 | G33: =PMT(rate/12, Term-12, -Amount) -> 487303.68 | H33: =D33-F33 -> 2816086.8
B34: =B33+1 -> 31 | C34: =EDATE(C33, 1) -> 46539 | D34: =H33 -> 2816086.8 | E34: =D34*(rate/12) -> 30507.607 | F34: =G34-E34 -> 456796.07 | G34: =PMT(rate/12, Term-12, -Amount) -> 487303.68 | H34: =D34-F34 -> 2359290.7
... B39: =B38+1 -> 36 | C39: =EDATE(C38, 1) -> 46692 | D39: =H38 -> 482081.14 | E39: =D39*(rate/12) -> 5222.5456 | F39: =G39-E39 -> 482081.14 | G39: =PMT(rate/12, Term-12, -Amount) -> 487303.68 | H39: =D39-F39 -> 1.1641532e-09
C41: Summary
C42: Total Payments | F42: =SUM(G3:G39) -> 11695288
C43: Total Principal Paid | F43: =SUM(F4:F39) -> 10250000
C44: Total Interest Accumulated | F44: =SUM(E4:E39) -> 1445288.4
C45: Total Cost of Loan | F45: =interest_Reserve+F42 -> 12422977
...

Sheet Sensitivity
B2: Sensitivity Analysis - Total Interest Earned
B3: Rate \ Term | C3: 24 Mo | D3: 30 Mo | E3: 36 Mo | F3: 42 Mo | G3: 48 Mo
B4: 0.1 | C4: =-PMT(tblSensitivity[[#This Row],[Rate \ Term]]/12,12,Amount)*12 -Amount -> 563654.13 | D4: =-PMT(tblSensitivity[[#This Row],[Rate \ Term]]/12,18, Amount)*18-Amount -> 830531.26 | E4: =-PMT(tblSensitivity[[#This Row],[Rate \ Term]]/12,24,Amount)*24 -Amount -> 1101651.9 | F4: =-PMT(tblSensitivity[[#This Row],[Rate \ Term]]/12,30,Amount)*30 -Amount -> 1377008.6 | G4: =-PMT(tblSensitivity[[#This Row],[Rate \ Term]]/12,36,Amount)*36 -Amount -> 1656592.1
B5: 0.11 | C5: =-PMT(tblSensitivity[[#This Row],[Rate \ Term]]/12,12,Amount)*12 -Amount -> 620944 | D5: =-PMT(tblSensitivity[[#This Row],[Rate \ Term]]/12,18, Amount)*18-Amount -> 915671.07 | E5: =-PMT(tblSensitivity[[#This Row],[Rate \ Term]]/12,24,Amount)*24 -Amount -> 1215528.2 | F5: =-PMT(tblSensitivity[[#This Row],[Rate \ Term]]/12,30,Amount)*30 -Amount -> 1520504.6 | G5: =-PMT(tblSensitivity[[#This Row],[Rate \ Term]]/12,36,Amount)*36 -Amount -> 1830586.6
B6: 0.12 | C6: =-PMT(tblSensitivity[[#This Row],[Rate \ Term]]/12,12,Amount)*12 -Amount -> 678401.01 | D6: =-PMT(tblSensitivity[[#This Row],[Rate \ Term]]/12,18, Amount)*18-Amount -> 1001187.8 | E6: =-PMT(tblSensitivity[[#This Row],[Rate \ Term]]/12,24,Amount)*24 -Amount -> 1330074.2 | F6: =-PMT(tblSensitivity[[#This Row],[Rate \ Term]]/12,30,Amount)*30 -Amount -> 1665044.8 | G6: =-PMT(tblSensitivity[[#This Row],[Rate \ Term]]/12,36,Amount)*36 -Amount -> 2006080.3
B7: 0.13 | C7: =-PMT(tblSensitivity[[#This Row],[Rate \ Term]]/12,12,Amount)*12 -Amount -> 736024.91 | D7: =-PMT(tblSensitivity[[#This Row],[Rate \ Term]]/12,18, Amount)*18-Amount -> 1087080.9 | E7: =-PMT(tblSensitivity[[#This Row],[Rate \ Term]]/12,24,Amount)*24 -Amount -> 1445288.4 | F7: =-PMT(tblSensitivity[[#This Row],[Rate \ Term]]/12,30,Amount)*30 -Amount -> 1810626.4 | G7: =-PMT(tblSensitivity[[#This Row],[Rate \ Term]]/12,36,Amount)*36 -Amount -> 2183068.3
B8: 0.14 | C8: =-PMT(tblSensitivity[[#This Row],[Rate \ Term]]/12,12,Amount)*12 -Amount -> 793815.47 | D8: =-PMT(tblSensitivity[[#This Row],[Rate \ Term]]/12,18, Amount)*18-Amount -> 1173349.6 | E8: =-PMT(tblSensitivity[[#This Row],[Rate \ Term]]/12,24,Amount)*24 -Amount -> 1561169.3 | F8: =-PMT(tblSensitivity[[#This Row],[Rate \ Term]]/12,30,Amount)*30 -Amount -> 1957246.5 | G8: =-PMT(tblSensitivity[[#This Row],[Rate \ Term]]/12,36,Amount)*36 -Amount -> 2361545.4
B9: 0.15 | C9: =-PMT(tblSensitivity[[#This Row],[Rate \ Term]]/12,12,Amount)*12 -Amount -> 851772.42 | D9: =-PMT(tblSensitivity[[#This Row],[Rate \ Term]]/12,18, Amount)*18-Amount -> 1259993.3 | E9: =-PMT(tblSensitivity[[#This Row],[Rate \ Term]]/12,24,Amount)*24 -Amount -> 1677715.4 | F9: =-PMT(tblSensitivity[[#This Row],[Rate \ Term]]/12,30,Amount)*30 -Amount -> 2104902.1 | G9: =-PMT(tblSensitivity[[#This Row],[Rate \ Term]]/12,36,Amount)*36 -Amount -> 2541506.2
B11: * Term includes 12-month deferral period. Interest calculated on active payment months only (term minus 12). Current deal highlighted.
B13: Sensitivity Analysis - Minimum Annual DSCR by Rate & Term
B14: Rate \ Term | C14: 24 Mo | D14: 30 Mo | E14: 36 Mo | F14: 42 Mo | G14: 48 Mo
B15: 0.1 | C15: ='Cash Flow'!$F$15/(PMT(tblSensitivityDSCR[[#This Row],[Rate \ Term]]/12, 12, -Amount)*12) -> 1.3112683 | D15: ='Cash Flow'!$F$15/(PMT(tblSensitivityDSCR[[#This Row],[Rate \ Term]]/12, 18, -Amount)*12) -> 1.9195292 | E15: ='Cash Flow'!$F$15/(PMT(tblSensitivityDSCR[[#This Row],[Rate \ Term]]/12, 24, -Amount)*12) -> 2.4982447 | F15: ='Cash Flow'!$F$15/(PMT(tblSensitivityDSCR[[#This Row],[Rate \ Term]]/12, 30, -Amount)*12) -> 3.04885 | G15: ='Cash Flow'!$F$15/(PMT(tblSensitivityDSCR[[#This Row],[Rate \ Term]]/12, 36, -Amount)*12) -> 3.5727105
B16: 0.11 | C16: ='Cash Flow'!$F$15/(PMT(tblSensitivityDSCR[[#This Row],[Rate \ Term]]/12, 12, -Amount)*12) -> 1.3043579 | D16: ='Cash Flow'!$F$15/(PMT(tblSensitivityDSCR[[#This Row],[Rate \ Term]]/12, 18, -Amount)*12) -> 1.9048925 | E16: ='Cash Flow'!$F$15/(PMT(tblSensitivityDSCR[[#This Row],[Rate \ Term]]/12, 24, -Amount)*12) -> 2.473432 | F16: ='Cash Flow'!$F$15/(PMT(tblSensitivityDSCR[[#This Row],[Rate \ Term]]/12, 30, -Amount)*12) -> 3.011681 | G16: ='Cash Flow'!$F$15/(PMT(tblSensitivityDSCR[[#This Row],[Rate \ Term]]/12, 36, -Amount)*12) -> 3.5212534
B17: 0.12 | C17: ='Cash Flow'!$F$15/(PMT(tblSensitivityDSCR[[#This Row],[Rate \ Term]]/12, 12, -Amount)*12) -> 1.2975002 | D17: ='Cash Flow'!$F$15/(PMT(tblSensitivityDSCR[[#This Row],[Rate \ Term]]/12, 18, -Amount)*12) -> 1.890414 | E17: ='Cash Flow'!$F$15/(PMT(tblSensitivityDSCR[[#This Row],[Rate \ Term]]/12, 24, -Amount)*12) -> 2.4489657 | F17: ='Cash Flow'!$F$15/(PMT(tblSensitivityDSCR[[#This Row],[Rate \ Term]]/12, 30, -Amount)*12) -> 2.9751466 | G17: ='Cash Flow'!$F$15/(PMT(tblSensitivityDSCR[[#This Row],[Rate \ Term]]/12, 36, -Amount)*12) -> 3.4708329
B18: 0.13 | C18: ='Cash Flow'!$F$15/(PMT(tblSensitivityDSCR[[#This Row],[Rate \ Term]]/12, 12, -Amount)*12) -> 1.2906945 | D18: ='Cash Flow'!$F$15/(PMT(tblSensitivityDSCR[[#This Row],[Rate \ Term]]/12, 18, -Amount)*12) -> 1.8760917 | E18: ='Cash Flow'!$F$15/(PMT(tblSensitivityDSCR[[#This Row],[Rate \ Term]]/12, 24, -Amount)*12) -> 2.4248401 | F18: ='Cash Flow'!$F$15/(PMT(tblSensitivityDSCR[[#This Row],[Rate \ Term]]/12, 30, -Amount)*12) -> 2.9392342 | G18: ='Cash Flow'!$F$15/(PMT(tblSensitivityDSCR[[#This Row],[Rate \ Term]]/12, 36, -Amount)*12) -> 3.4214247
B19: 0.14 | C19: ='Cash Flow'!$F$15/(PMT(tblSensitivityDSCR[[#This Row],[Rate \ Term]]/12, 12, -Amount)*12) -> 1.2839405 | D19: ='Cash Flow'!$F$15/(PMT(tblSensitivityDSCR[[#This Row],[Rate \ Term]]/12, 18, -Amount)*12) -> 1.8619235 | E19: ='Cash Flow'!$F$15/(PMT(tblSensitivityDSCR[[#This Row],[Rate \ Term]]/12, 24, -Amount)*12) -> 2.4010497 | F19: ='Cash Flow'!$F$15/(PMT(tblSensitivityDSCR[[#This Row],[Rate \ Term]]/12, 30, -Amount)*12) -> 2.9039313 | G19: ='Cash Flow'!$F$15/(PMT(tblSensitivityDSCR[[#This Row],[Rate \ Term]]/12, 36, -Amount)*12) -> 3.3730051
B20: 0.15 | C20: ='Cash Flow'!$F$15/(PMT(tblSensitivityDSCR[[#This Row],[Rate \ Term]]/12, 12, -Amount)*12) -> 1.2772377 | D20: ='Cash Flow'!$F$15/(PMT(tblSensitivityDSCR[[#This Row],[Rate \ Term]]/12, 18, -Amount)*12) -> 1.8479075 | E20: ='Cash Flow'!$F$15/(PMT(tblSensitivityDSCR[[#This Row],[Rate \ Term]]/12, 24, -Amount)*12) -> 2.3775889 | F20: ='Cash Flow'!$F$15/(PMT(tblSensitivityDSCR[[#This Row],[Rate \ Term]]/12, 30, -Amount)*12) -> 2.8692259 | G20: ='Cash Flow'!$F$15/(PMT(tblSensitivityDSCR[[#This Row],[Rate \ Term]]/12, 36, -Amount)*12) -> 3.325551
B22: *DSCR based on minimum annual net income available for debt service (2026-27 season). Minimum guideline: 2.50x. Current deal highlighted.

Sheet Inputs
C2: INPUTS
C3: Gross Loan Amount | D3: 10250000
C4: Interest | D4: 0.13
C5: Term (Months) | D5: 36
C6: Origination Fee (1%) | D6: =0.01*D3 -> 102500
C7: Underwriting Fee (3%) | D7: =D3*0.03 -> 307500
C8: Death & Disgrace Insurance (est) | D8: 190050
C9: Interest Reserve (est) | D9: 727689
C10: Cash Reserve (Depository) 10% of Outstanding Balance | D10: =10%*Amount -> 1025000
C11: Total Upfront | D11: =SUM(D6:D10) -> 2352739
C12: Monthly PMT (Defered 12 months) | D12: =PMT(rate/12, (Term-12), -Amount) -> 487303.68
C13: Annual Debt service | D13: =PMT_Mnth*12 -> 5847644.2
C14: Annual Income | D14: =Contract_Y2 -> 31022727
C15: Monthly Income | D15: =D14/12 -> 2585227.2
C16: Monthly Debt (Total) | D16: ='Cash Flow'!D26/12 -> 60153.748
C17: Contract Value | D17: =Salary_Remain -> 86931818
C18: Credit Score | D18: 680
B21: PERSONAL RESIDENCE, REAL ESTATE INVESTMENTS, & MORTGAGE DEBT
B22: Personal Residence Address | C22: Loan Balance | D22: PMT | E22: Rate | F22: Maturity | G22: Principal | H22: Origination Date
B23: 123 Brookstone Manor, New York, NY | C23: 1970000 | D23: 9525 | E23: 0.0395 | F23: 55617 | G23: =PV(tblProperty15[[#This Row],[Rate]]/12, 360, -tblProperty15[[#This Row],[PMT]]) -> 2007218.7 | H23: 2022
B24: 709 Palmview Drive, Miami, FL | C24: 2863000 | D24: 19190 | E24: 0.0695 | F24: 56126 | G24: =PV(tblProperty15[[#This Row],[Rate]]/12, 360, -tblProperty15[[#This Row],[PMT]]) -> 2899019.7 | H24: 08/31/2023
B25: 33276 Queens Colony, Bethesda, MD | C25: 477000 | D25: 3200 | E25: 0.0695 | F25: 56084 | G25: =PV(E25/12, 360, -tblProperty15[[#This Row],[PMT]]) -> 483421.73 | H25: 2022
B26: Investment Property Address | C26: Loan Balance | D26: PMT | E26: Rate | F26: Maturity | G26: Principal | H26: Origination Date
B27: 7 & 15 South Street, Los Angeles, CA | C27: 1000000 | D27: 6722 | E27: 0.08 | F27: 55501 | G27: =PV(tblProperty15[[#This Row],[Rate]]/12, 360, -tblProperty15[[#This Row],[PMT]]) -> 916097.65 | H27: 5/20/2021

Sheet PFS
B2: Personal Financial Statement
B3: Assets | E3: Liabilities
B5: Cash & Cash Equivalents | E5: Proposed Debt
B6: Cash on Hand | C6: 2158502 | E6: Proposed Guaranteed Contract Loan | F6: =Amount -> 10250000
B7: Marketable Securities | C7: 1300000
B8: Total Cash & Cash Equivalents | C8: =SUM(C6:C7) -> 3458502 | E8: Installment & Personal Debt
E9: Pierce Advisors | F9: 1900000
B10: Contract & Investment Assets | E10: Credit Cards (Amex) | F10: 92768
B11: Guaranteed NBA Contract (Remaining) | C11: =Salary_Remain -> 86931818 | E11: Auto (KG Financial) | F11: 44010
B12: Various Partnerships | C12: 7165498 | E12: Total Installment & Personal Debt | F12: =SUM(F9:F11) -> 2036778
B13: Total Contract & Investment Assets | C13: =SUM(C11:C12) -> 94097316
E14: Mortgage Debt
B15: Real Estate | E15: 123 Brookstone Manor, NY | F15: 1970000
B16: 123 Brookstone Manor, NY | C16: 2600000 | E16: 709 Palmview Dr, Miami FL | F16: 2863000
B17: 709 Palmview Dr, Miami FL | C17: 4100000 | E17: 33276 Queens Colony, Bethesda, MD | F17: 477000
B18: 33276 Queens Colony, Bethesda, MD | C18: 638000 | E18: 7 & 15 South Street, Los Angeles, CA | F18: 1000000
B19: 7 & 15 South Street, Los Angeles, CA | C19: 1000000 | E19: Total Mortgage Debt | F19: =SUM(F15:F18) -> 6310000
B20: Total Real Estate | C20: =SUM(C16:C19) -> 8338000
B22: Automobiles, Boats & Vessels
B23: Automobile (Adjusted for Depreciation) | C23: 22500
B24: Total Automobiles, Boats & Vessels | C24: =C23 -> 22500
B26: Personal Property
B27: Watch Collection/Jewelry | C27: 3100000
B28: Artwork | C28: 1800000
B29: Total Personal Property | C29: =SUM(C27:C28) -> 4900000
B31: TOTAL ASSETS | C31: =SUM(C29,C24,C20,C13,C8) -> 110816318 | E31: TOTAL LIABILITIES | F31: =SUM(F19,F12,F6) -> 18596778
B32: NET WORTH | F32: =Assets-Liabilities -> 92219540
B34: ANNUAL INCOME SUMMARY (Supplemental)
B35: NBA Contract Income | F35: =Contract_Y2 -> 31022727
B36: Rental Income | F36: 96000
B37: Interest Income | F37: 120000
B38: Dividend Income | F38: 20000
B39: Total Annual Income | F39: =SUM(F35:F38) -> 31258727

Sheet Contract
B3: UNIFORM PLAYER CONTRACT
B4: Exhibit 1 - Compensation
B6: Player: | C6: Player A
B7: Team: | C7: ABC Team
B8: Date: | C8: 45080
B10: Season | C10: Current Base Compensation | D10: Deferred Base Compensation
B11: 2023 - 24 | C11: =Contract_Y1 -> 33068182 | D11: N/A
B12: 2024 - 25 | C12: =Contract_Y2 -> 31022727 | D12: N/A
B13: 2025 - 26 | C13: =Contract_Y3 -> 28977273 | D13: N/A
B14: 2026 - 27 | C14: =Contract_Y4 -> 26931818 | D14: N/A
B17: NBA Season | C17: Base Salary | D17: Signing Bonus | E17: Total
B18: 2023-24 | C18: 33068182 | D18: 0 | E18: 33068182
B19: Received | C19: =Contract_Y1 -> 33068182 | D19: 0 | E19: =E18 -> 33068182
B20: 2024-25 | C20: 31022727 | D20: 0 | E20: 31022727
B21: 2025-26 | C21: 28977273 | D21: 0 | E21: 28977273
B22: 2026-27 | C22: 26931818 | D22: 0 | E22: 26931818
B23: Remaining | C23: =SUM(C20:C22) -> 86931818 | D23: 0 | E23: =SUM(E20:E22) -> 86931818
B24: Totals | C24: =C19+Salary_Remain -> 120000000 | D24: 0 | E24: =E19+E23 -> 120000000
